<?xml version="0.0" ?>
<robot name="">
    <link name="torso">
        <inertial>
            <!-- mass, inertia will be overwritten-->
            <mass value="1"/>
            <inertia ixx="1" ixy="0" ixz="0" iyy="1" iyz="0" izz="1"/>
        </inertial>
        <collision>
            <geometry>
                <box size="0.12 0.32 0.20"/>
            </geometry>
        </collision>
    </link>

    <link name="head">
        <inertial>
            <!-- mass, inertia will be overwritten-->
            <mass value="1"/>
            <inertia ixx="1" ixy="0" ixz="0" iyy="1" iyz="0" izz="1"/>
        </inertial>
        <collision>
            <geometry>
                <box size="0.12 0.14 0.14"/>
            </geometry>
        </collision>
    </link>

    <link name="link1_2">
        <inertial>
            <origin rpy="0.00000 -0.00000 0.00000" xyz="0.00000 0.00000 0.00000"/>
            <mass value="0.00000"/>
            <inertia ixx="0.00000" ixy="0" ixz="0" iyy="0.00000" iyz="0" izz="0.00000"/>
        </inertial>
    </link>

    <link name="lwaist">
        <inertial>
            <!-- mass, inertia will be overwritten-->
            <mass value="1"/>
            <inertia ixx="1" ixy="0" ixz="0" iyy="1" iyz="0" izz="1"/>
        </inertial>
        <collision>
            <geometry>
                <box size="0.12 0.18 0.12"/>
            </geometry>
        </collision>
    </link>

    <link name="pelvis">
        <inertial>
            <!-- mass, inertia will be overwritten-->
            <mass value="1"/>
            <inertia ixx="1" ixy="0" ixz="0" iyy="1" iyz="0" izz="1"/>
        </inertial>
        <collision>
            <geometry>
                <box size="0.14 0.24 0.18"/>
            </geometry>
        </collision>
    </link>

    <link name="link1_7">
        <inertial>
            <origin rpy="0.00000 -0.00000 0.00000" xyz="0.00000 0.00000 0.00000"/>
            <mass value="0.00000"/>
            <inertia ixx="0.00000" ixy="0" ixz="0" iyy="0.00000" iyz="0" izz="0.00000"/>
        </inertial>
    </link>

    <link name="link1_8">
        <inertial>
            <origin rpy="0.00000 -0.00000 0.00000" xyz="0.00000 0.00000 0.00000"/>
            <mass value="0.00000"/>
            <inertia ixx="0.00000" ixy="0" ixz="0" iyy="0.00000" iyz="0" izz="0.00000"/>
        </inertial>
    </link>

    <link name="right_thigh">
        <inertial>
            <origin rpy="0.0 -0.00000 0.00000" xyz="0.00000 0.00500 -0.17000"/>
            <!-- mass, inertia will be overwritten-->
            <mass value="1"/>
            <inertia ixx="1" ixy="0" ixz="0" iyy="1" iyz="0" izz="1"/>
        </inertial>
        <collision>
            <origin rpy="0.0 -0.00000 0.00000" xyz="0.00000 0.00500 -0.17000"/>
            <geometry>
                <box size="0.12 0.12 0.34"/>
            </geometry>
        </collision>
    </link>

    <link name="right_shin">
        <inertial>
            <origin rpy="0.0 -0.00000 0.0" xyz="0.00000 0.00000 -0.125000"/>
            <!-- mass, inertia will be overwritten-->
            <mass value="1"/>
            <inertia ixx="1" ixy="0" ixz="0" iyy="1" iyz="0" izz="1"/>
        </inertial>
        <collision>
            <origin rpy="0.0 -0.00000 0.0" xyz="0.00000 0.00000 -0.125000"/>
            <geometry>
                <box size="0.1 0.1 0.25"/>
            </geometry>
        </collision>
    </link>

    <link name="link1_13">
        <inertial>
            <origin rpy="0.00000 -0.00000 0.00000" xyz="0.00000 0.00000 0.00000"/>
            <mass value="0.00000"/>
            <inertia ixx="0.00000" ixy="0" ixz="0" iyy="0.00000" iyz="0" izz="0.00000"/>
        </inertial>
    </link>

    <link name="right_foot">
        <inertial>
            <origin rpy="0.00000 -0.00000 0.00000" xyz="0.03500 0.01000 0.00000"/>
            <!-- mass, inertia will be overwritten-->
            <mass value="1"/>
            <inertia ixx="1" ixy="0" ixz="0" iyy="1" iyz="0" izz="1"/>
        </inertial>
        <collision>
            <origin rpy="0.0 -0.00000 0.0" xyz="0.035000 0.01000 -0.000"/>
            <geometry>
                <box size="0.25 0.14 0.05"/>
            </geometry>
        </collision>
    </link>

    <link name="link1_16">
        <inertial>
            <origin rpy="0.00000 -0.00000 0.00000" xyz="0.00000 0.00000 0.00000"/>
            <mass value="0.00000"/>
            <inertia ixx="0.00000" ixy="0" ixz="0" iyy="0.00000" iyz="0" izz="0.00000"/>
        </inertial>
    </link>
    <link name="link1_17">
        <inertial>
            <origin rpy="0.00000 -0.00000 0.00000" xyz="0.00000 0.00000 0.00000"/>
            <mass value="0.00000"/>
            <inertia ixx="0.00000" ixy="0" ixz="0" iyy="0.00000" iyz="0" izz="0.00000"/>
        </inertial>
    </link>

    <link name="left_thigh">
        <!--		same as right thigh-->
        <inertial>
            <origin rpy="0.0 -0.00000 0.00000" xyz="0.00000 0.00500 -0.17000"/>
            <!-- mass, inertia will be overwritten-->
            <mass value="1"/>
            <inertia ixx="1" ixy="0" ixz="0" iyy="1" iyz="0" izz="1"/>
        </inertial>
        <collision>
            <origin rpy="0.0 -0.00000 0.00000" xyz="0.00000 0.00500 -0.17000"/>
            <geometry>
                <box size="0.12 0.12 0.34"/>
            </geometry>
        </collision>
    </link>

    <link name="left_shin">
        <inertial>
            <origin rpy="0.00000 -0.00000 0.00000" xyz="0.00000 0.00000 -0.125000"/>
            <!-- mass, inertia will be overwritten-->
            <mass value="1"/>
            <inertia ixx="1" ixy="0" ixz="0" iyy="1" iyz="0" izz="1"/>
        </inertial>
        <collision>
            <origin rpy="0.0 -0.00000 0.0" xyz="0.00000 0.00000 -0.125000"/>
            <geometry>
                <box size="0.1 0.1 0.25"/>
            </geometry>
        </collision>
    </link>

    <link name="link1_22">
        <inertial>
            <origin rpy="0.00000 -0.00000 0.00000" xyz="0.00000 0.00000 0.00000"/>
            <mass value="0.00000"/>
            <inertia ixx="0.00000" ixy="0" ixz="0" iyy="0.00000" iyz="0" izz="0.00000"/>
        </inertial>
    </link>

    <link name="left_foot">
        <inertial>
            <origin rpy="0.0 -0.00000 0.0" xyz="0.035000 -0.01000 -0.000"/>
            <!-- mass, inertia will be overwritten-->
            <mass value="1"/>
            <inertia ixx="1" ixy="0" ixz="0" iyy="1" iyz="0" izz="1"/>
        </inertial>
        <collision>
            <origin rpy="0.0 -0.00000 0.0" xyz="0.035000 -0.01000 -0.000"/>
            <geometry>
                <box size="0.25 0.14 0.05"/>
            </geometry>
        </collision>
    </link>

    <link name="link1_25">
        <inertial>
            <origin rpy="0.00000 -0.00000 0.00000" xyz="0.00000 0.00000 0.00000"/>
            <mass value="0.00000"/>
            <inertia ixx="0.00000" ixy="0" ixz="0" iyy="0.00000" iyz="0" izz="0.00000"/>
        </inertial>
    </link>

    <link name="right_upper_arm">
        <inertial>
            <origin rpy="0 0 0" xyz="0.0 0 -0.15000"/>
            <!-- mass, inertia will be overwritten-->
            <mass value="1"/>
            <inertia ixx="1" ixy="0" ixz="0" iyy="1" iyz="0" izz="1"/>
        </inertial>
        <collision>
            <origin rpy="0 0 0" xyz="0.0 0 -0.15000"/>
            <geometry>
                <box size="0.08 0.08 0.30"/>
            </geometry>
        </collision>
    </link>

    <link name="right_lower_arm">
        <inertial>
            <origin rpy="0 0 0" xyz="0.0 0 -0.12000"/>
            <!-- mass, inertia will be overwritten-->
            <mass value="1"/>
            <inertia ixx="1" ixy="0" ixz="0" iyy="1" iyz="0" izz="1"/>
        </inertial>
        <collision>
            <origin rpy="0 0 0" xyz="0.0 0 -0.12000"/>
            <geometry>
                <box size="0.06 0.06 0.24"/>
            </geometry>
        </collision>
    </link>

    <link name="right_hand">
        <inertial>
            <origin rpy="0.00000 -0.00000 0.00000" xyz="0 0 0"/>
            <!-- mass, inertia will be overwritten-->
            <mass value="1"/>
            <inertia ixx="1" ixy="0" ixz="0" iyy="1" iyz="0" izz="1"/>
        </inertial>
        <collision>
            <origin rpy="0.00000 -0.00000 0.00000" xyz="0 0 0"/>
            <geometry>
                <box size="0.06 0.12 0.20"/>
            </geometry>
        </collision>
    </link>

    <link name="link1_30">
        <inertial>
            <origin rpy="0.00000 -0.00000 0.00000" xyz="0.00000 0.00000 0.00000"/>
            <mass value="0.00000"/>
            <inertia ixx="0.00000" ixy="0" ixz="0" iyy="0.00000" iyz="0" izz="0.00000"/>
        </inertial>
    </link>

    <link name="left_upper_arm">
        <inertial>
            <origin rpy="0 0 0" xyz="0.0 0 -0.15000"/>
            <!-- mass, inertia will be overwritten-->
            <mass value="1"/>
            <inertia ixx="1" ixy="0" ixz="0" iyy="1" iyz="0" izz="1"/>
        </inertial>
        <collision>
            <origin rpy="0 0 0" xyz="0.0 0 -0.15000"/>
            <geometry>
                <box size="0.08 0.08 0.30"/>
            </geometry>
        </collision>
    </link>

    <link name="left_lower_arm">
        <inertial>
            <origin rpy="0 0 0" xyz="0.0 0 -0.12000"/>
            <!-- mass, inertia will be overwritten-->
            <mass value="1"/>
            <inertia ixx="1" ixy="0" ixz="0" iyy="1" iyz="0" izz="1"/>
        </inertial>
        <collision>
            <origin rpy="0 0 0" xyz="0.0 0 -0.12000"/>
            <geometry>
                <box size="0.06 0.06 0.24"/>
            </geometry>
        </collision>
    </link>

    <link name="left_hand">
        <inertial>
            <origin rpy="0.00000 -0.00000 0.00000" xyz="0 0 0"/>
            <!-- mass, inertia will be overwritten-->
            <mass value="1"/>
            <inertia ixx="1" ixy="0" ixz="0" iyy="1" iyz="0" izz="1"/>
        </inertial>
        <collision>
            <origin rpy="0.00000 -0.00000 0.00000" xyz="0 0 0"/>
            <geometry>
                <box size="0.06 0.12 0.20"/>
            </geometry>
        </collision>
    </link>

    <joint name="abdomen_z" type="revolute">
        <parent link="torso"/>
        <child link="link1_2"/>
        <dynamics damping="1.0" friction="0.001"/>
        <origin rpy="0.00000 -0.00400 0.00000" xyz="-0.01026 0.00000 -0.12500"/>
        <axis xyz="0.00000 0.00000 1.00000"/>
        <limit lower="-1.0471975512" upper="1.0471975512"/>
    </joint>
    <joint name="abdomen_y" type="revolute">
        <parent link="link1_2"/>
        <child link="lwaist"/>
        <dynamics damping="1.0" friction="0.001"/>
        <origin rpy="0.00000 -0.00000 0.00000" xyz="0.00000 0.00000 -0.06500"/>
        <axis xyz="0.00000 1.00000 0.00000"/>
        <limit lower="-1.0471975512" upper="1.0471975512"/>
    </joint>
    <joint name="abdomen_x" type="revolute">
        <parent link="lwaist"/>
        <child link="pelvis"/>
        <dynamics damping="1.0" friction="0.001"/>
        <origin rpy="0.00000 -0.00400 0.00000" xyz="0.0000 0.00000 -0.16500"/>
        <axis xyz="1.00000 0.00000 0.00000"/>
        <limit lower="-1.0471975512" upper="1.0471975512"/>
    </joint>

    <joint name="right_hip_x" type="revolute">
        <parent link="pelvis"/>
        <child link="link1_7"/>
        <dynamics damping="1.0" friction="0.001"/>
        <origin rpy="0.00000 -0.00000 0.00000" xyz="0.00000 -0.10000 -0.10000"/>
        <axis xyz="1.00000 0.00000 0.00000"/>
        <limit lower="-1.57" upper="1.57"/>
    </joint>
    <joint name="right_hip_z" type="revolute">
        <parent link="link1_7"/>
        <child link="link1_8"/>
        <dynamics damping="1.0" friction="0.001"/>
        <origin rpy="0.00000 -0.00000 0.00000" xyz="0.00000 0.00000 0.00000"/>
        <axis xyz="0.00000 0.00000 1.00000"/>
        <limit lower="-1.0471975512" upper="1.0471975512"/>
    </joint>
    <joint name="right_hip_y" type="revolute">
        <parent link="link1_8"/>
        <child link="right_thigh"/>
        <dynamics damping="1.0" friction="0.001"/>
        <origin rpy="0.00000 -0.00000 0.00000" xyz="0.00000 0.00000 0.00000"/>
        <axis xyz="0.00000 1.00000 0.00000"/>
        <limit lower="-2.57" upper="2.57"/>
    </joint>

    <joint name="right_knee" type="revolute">
        <parent link="right_thigh"/>
        <child link="right_shin"/>
        <dynamics damping="1.0" friction="0.001"/>
        <origin rpy="0.00000 -0.00000 0.00000" xyz="0.00000 0.01000 -0.38300"/>
        <axis xyz="0.00000 1.00000 0.00000"/>
        <limit lower="0" upper="2.8"/>
    </joint>

    <joint name="right_ankle_y" type="revolute">
        <parent link="right_shin"/>
        <child link="link1_13"/>
        <dynamics damping="1.0" friction="0.001"/>
        <origin rpy="0.00000 -0.00000 0.00000" xyz="0.00000 0.00000 -0.31000"/>
        <axis xyz="0.00000 1.00000 0.00000"/>
        <limit lower="-1.0471975512" upper="1.5771975512"/>
    </joint>
    <joint name="right_ankle_x" type="revolute">
        <parent link="link1_13"/>
        <child link="right_foot"/>
        <dynamics damping="1.0" friction="0.001"/>
        <origin rpy="0.00000 -0.00000 0.00000" xyz="0.00000 0.00000 -0.04000"/>
        <axis xyz="1.00000 0.00000 0.50000"/>
        <limit lower="-1.0471975512" upper="1.0471975512"/>
    </joint>

    <joint name="left_hip_x" type="revolute">
        <parent link="pelvis"/>
        <child link="link1_16"/>
        <dynamics damping="1.0" friction="0.001"/>
        <origin rpy="0.00000 -0.00000 0.00000" xyz="0.00000 0.10000 -0.10000"/>
        <axis xyz="-1.00000 0.00000 0.00000"/>
        <limit lower="-1.57" upper="1.57"/>
    </joint>
    <joint name="left_hip_z" type="revolute">
        <parent link="link1_16"/>
        <child link="link1_17"/>
        <dynamics damping="1.0" friction="0.001"/>
        <origin rpy="0.00000 -0.00000 0.00000" xyz="0.00000 0.00000 0.00000"/>
        <axis xyz="0.00000 0.00000 -1.00000"/>
        <limit lower="-1.0471975512" upper="1.0471975512"/>
    </joint>
    <joint name="left_hip_y" type="revolute">
        <parent link="link1_17"/>
        <child link="left_thigh"/>
        <dynamics damping="1.0" friction="0.001"/>
        <origin rpy="0.00000 -0.00000 0.00000" xyz="0.00000 0.00000 0.00000"/>
        <axis xyz="0.00000 1.00000 0.00000"/>
        <limit lower="-2.57" upper="2.57"/>
    </joint>

    <joint name="left_knee" type="revolute">
        <parent link="left_thigh"/>
        <child link="left_shin"/>
        <dynamics damping="1.0" friction="0.001"/>
        <origin rpy="0.00000 -0.00000 0.00000" xyz="0.00000 -0.01000 -0.38300"/>
        <axis xyz="0.00000 1.00000 0.00000"/>
        <limit lower="0" upper="2.8"/>
    </joint>

    <joint name="left_ankle_y" type="revolute">
        <parent link="left_shin"/>
        <child link="link1_22"/>
        <dynamics damping="1.0" friction="0.001"/>
        <origin rpy="0.00000 -0.00000 0.00000" xyz="0.00000 0.00000 -0.31000"/>
        <axis xyz="0.00000 1.00000 0.00000"/>
        <limit lower="-1.0471975512" upper="1.5771975512"/>
    </joint>
    <joint name="left_ankle_x" type="revolute">
        <parent link="link1_22"/>
        <child link="left_foot"/>
        <dynamics damping="1.0" friction="0.001"/>
        <origin rpy="0.00000 -0.00000 0.00000" xyz="0.00000 0.00000 -0.04000"/>
        <axis xyz="-1.00000 0.00000 -0.50000"/>
        <limit lower="-1.0471975512" upper="1.0471975512"/>
    </joint>

    <joint name="right_shoulder1" type="revolute">
        <parent link="torso"/>
        <child link="link1_25"/>
        <dynamics damping="1.0" friction="0.001"/>
        <origin rpy="0.00000 -0.00000 0.00000" xyz="0.00000 -0.24000 0.06000"/>
        <axis xyz="0.00000 -1.00000 0.00000"/>
        <limit lower="-2.57" upper="3.14"/>
    </joint>
    <joint name="right_shoulder2" type="revolute">
        <parent link="link1_25"/>
        <child link="right_upper_arm"/>
        <dynamics damping="1.0" friction="0.001"/>
        <origin rpy="0.00000 -0.00000 0.00000" xyz="0.00000 0.00000 0.00000"/>
        <axis xyz="1.00000 0.00000 0.00000"/>
        <limit lower="-3.14" upper="2.57"/>
    </joint>

    <joint name="right_elbow" type="revolute">
        <parent link="right_upper_arm"/>
        <child link="right_lower_arm"/>
        <dynamics damping="1.0" friction="0.001"/>
        <origin rpy="0.00000 -0.00000 0.00000" xyz="0 0 -0.30000"/>
        <axis xyz="0.00000 -1.00000 0.00000"/>
        <limit lower="0" upper="2.57"/>
    </joint>

    <joint name="right_wrist" type="revolute">
        <parent link="right_lower_arm"/>
        <child link="right_hand"/>
        <dynamics damping="1.0" friction="0.001"/>
        <origin rpy="0.00000 -0.00000 0.00000" xyz="0.00000 0.00000 -0.35000"/>
        <axis xyz="0 -1.00000 0.00000"/>
        <limit lower="-1.0471975512" upper="1.0471975512"/>
    </joint>

    <joint name="left_shoulder1" type="revolute">
        <parent link="torso"/>
        <child link="link1_30"/>
        <dynamics damping="1.0" friction="0.001"/>
        <origin rpy="0.00000 -0.00000 0.00000" xyz="0.00000 0.24000 0.06000"/>
        <axis xyz="0.00000 -1.00000 0.00000"/>
        <limit lower="-2.57" upper="3.14"/>
    </joint>
    <joint name="left_shoulder2" type="revolute">
        <parent link="link1_30"/>
        <child link="left_upper_arm"/>
        <dynamics damping="1.0" friction="0.001"/>
        <origin rpy="0.00000 -0.00000 0.00000" xyz="0.00000 0.00000 0.00000"/>
        <axis xyz="-1.00000 0.00000 0.00000"/>
        <limit lower="-3.14" upper="2.57"/>
    </joint>

    <joint name="left_elbow" type="revolute">
        <parent link="left_upper_arm"/>
        <child link="left_lower_arm"/>
        <dynamics damping="1.0" friction="0.001"/>
        <origin rpy="0.00000 -0.00000 0.00000" xyz="0 0 -0.30000"/>
        <axis xyz="0.00000 -1.00000 0.00000"/>
        <limit lower="0" upper="2.57"/>
    </joint>

    <joint name="left_wrist" type="revolute">
        <parent link="left_lower_arm"/>
        <child link="left_hand"/>
        <dynamics damping="1.0" friction="0.001"/>
        <origin rpy="0.00000 -0.00000 0.00000" xyz="0.00000 0.00000 -0.35000"/>
        <axis xyz="0 -1.00000 0.00000"/>
        <limit lower="-1.0471975512" upper="1.0471975512"/>
    </joint>

    <joint name="jointfix_head" type="fixed">
        <parent link="torso"/>
        <child link="head"/>
        <dynamics damping="1.0" friction="0.001"/>
        <origin rpy="0.00000 -0.00000 0.00000" xyz="0.00000 0.00000 0.19"/>
        <axis xyz="0.00000 0.00000 0.00000"/>
    </joint>
</robot>
